<!DOCTYPE html>
<html lang="zh-CN">
<head>
    <meta charset="UTF-8">
</head>
<body>
    <script>
        function print(str) {
            const p = document.createElement('p');
            p.innerText = str;
            document.body.appendChild(p);
        }
        // Promise 对象的错误具有“冒泡”性质，会一直向后传递，直到被捕获为止。也就是说，错误总是会被下一个catch语句捕获。
        new Promise((resolve, reject) => {
            reject('hello');
        })
        .then((res) => {
            print('resolve-1');
            return res;
        }, (rej) => {
            print('reject-1');
            return rej;
        })
        .then((res) => {
            print('resolve-2');
            print(res);
        })
        .catch((error) => {
            print('catch');
            print(error);
        });
        // reject-1 resolve-2 hello

        new Promise((resolve, reject) => {
            reject('hello');
        })
        .then((res) => {
            print('resolve-1');
            return res;
        })
        .then((res) => {
            print('resolve-2');
            print(res);
        })
        .catch((error) => {
            print('catch');
            print(error);
        });
        // catch hello
    </script>
</body>
</html>
